2018-04-09 16:04:21.759 [error] <0.1600.0> Supervisor 'Elixir.Logger.Supervisor' had child 'Elixir.Logger.ErrorHandler' started with 'Elixir.Logger.Watcher':start_link({error_logger,'Elixir.Logger.ErrorHandler',{true,false,500}}) at <0.1605.0> exit with reason normal in context child_terminated
2018-04-09 16:04:21.853 [error] <0.1661.0>@Elixir.GenServer:call CRASH REPORT Process <0.1661.0> with 0 neighbours exited with reason: no such process or port in call to 'Elixir.GenServer':call('Elixir.Ecto.Registry', {associate,<0.1661.0>,{'Elixir.Consumer.Repo','Elixir.Consumer.Repo.Pool',[{name,'Elixir.Consumer.Repo.Pool'},...]}}, 5000) in 'Elixir.GenServer':call/3 line 824
2018-04-09 16:04:21.854 [error] <0.1660.0>@Elixir.GenServer:call Supervisor 'Elixir.Consumer.Supervisor' had child 'Elixir.Consumer.Repo' started with 'Elixir.Consumer.Repo':start_link() at undefined exit with reason no such process or port in call to 'Elixir.GenServer':call('Elixir.Ecto.Registry', {associate,<0.1661.0>,{'Elixir.Consumer.Repo','Elixir.Consumer.Repo.Pool',[{name,'Elixir.Consumer.Repo.Pool'},...]}}, 5000) in context start_error
2018-04-09 16:05:15.994 [error] <0.191.0> Supervisor 'Elixir.Logger.Supervisor' had child 'Elixir.Logger.ErrorHandler' started with 'Elixir.Logger.Watcher':start_link({error_logger,'Elixir.Logger.ErrorHandler',{true,false,500}}) at <0.196.0> exit with reason normal in context child_terminated
2018-04-09 16:05:16.078 [error] <0.252.0>@Elixir.GenServer:call CRASH REPORT Process <0.252.0> with 0 neighbours exited with reason: no such process or port in call to 'Elixir.GenServer':call('Elixir.Ecto.Registry', {associate,<0.252.0>,{'Elixir.Consumer.Repo','Elixir.Consumer.Repo.Pool',[{name,'Elixir.Consumer.Repo.Pool'},...]}}, 5000) in 'Elixir.GenServer':call/3 line 824
2018-04-09 16:05:16.078 [error] <0.251.0>@Elixir.GenServer:call Supervisor 'Elixir.Consumer.Supervisor' had child 'Elixir.Consumer.Repo' started with 'Elixir.Consumer.Repo':start_link() at undefined exit with reason no such process or port in call to 'Elixir.GenServer':call('Elixir.Ecto.Registry', {associate,<0.252.0>,{'Elixir.Consumer.Repo','Elixir.Consumer.Repo.Pool',[{name,'Elixir.Consumer.Repo.Pool'},...]}}, 5000) in context start_error
2018-04-09 16:05:16.078 [error] <0.249.0> CRASH REPORT Process <0.249.0> with 0 neighbours exited with reason: {{shutdown,{failed_to_start_child,'Elixir.Consumer.Repo',{noproc,{'Elixir.GenServer',call,['Elixir.Ecto.Registry',{associate,<0.252.0>,{'Elixir.Consumer.Repo','Elixir.Consumer.Repo.Pool',[{name,'Elixir.Consumer.Repo.Pool'},{otp_app,consumer},{repo,'Elixir.Consumer.Repo'},{timeout,15000},{pool_timeout,5000},{adapter,'Elixir.Ecto.Adapters.Postgres'},{username,<<"postgres">>},{password,<<"postgres">>},{database,<<"consumer_dev">>},{hostname,<<"localhost">>},{pool_size,10},{pool,'Elixir.DBConnection.Poolboy'}]}},...]}}}},...} in application_master:init/4 line 134
2018-04-09 16:05:34.319 [error] <0.200.0> Supervisor 'Elixir.Logger.Supervisor' had child 'Elixir.Logger.ErrorHandler' started with 'Elixir.Logger.Watcher':start_link({error_logger,'Elixir.Logger.ErrorHandler',{true,false,500}}) at <0.205.0> exit with reason normal in context child_terminated
2018-04-09 16:05:34.408 [error] <0.261.0>@Elixir.GenServer:call CRASH REPORT Process <0.261.0> with 0 neighbours exited with reason: no such process or port in call to 'Elixir.GenServer':call('Elixir.Ecto.Registry', {associate,<0.261.0>,{'Elixir.Consumer.Repo','Elixir.Consumer.Repo.Pool',[{name,'Elixir.Consumer.Repo.Pool'},...]}}, 5000) in 'Elixir.GenServer':call/3 line 824
2018-04-09 16:05:34.408 [error] <0.260.0>@Elixir.GenServer:call Supervisor 'Elixir.Consumer.Supervisor' had child 'Elixir.Consumer.Repo' started with 'Elixir.Consumer.Repo':start_link() at undefined exit with reason no such process or port in call to 'Elixir.GenServer':call('Elixir.Ecto.Registry', {associate,<0.261.0>,{'Elixir.Consumer.Repo','Elixir.Consumer.Repo.Pool',[{name,'Elixir.Consumer.Repo.Pool'},...]}}, 5000) in context start_error
2018-04-09 16:05:34.408 [error] <0.258.0> CRASH REPORT Process <0.258.0> with 0 neighbours exited with reason: {{shutdown,{failed_to_start_child,'Elixir.Consumer.Repo',{noproc,{'Elixir.GenServer',call,['Elixir.Ecto.Registry',{associate,<0.261.0>,{'Elixir.Consumer.Repo','Elixir.Consumer.Repo.Pool',[{name,'Elixir.Consumer.Repo.Pool'},{otp_app,consumer},{repo,'Elixir.Consumer.Repo'},{timeout,15000},{pool_timeout,5000},{adapter,'Elixir.Ecto.Adapters.Postgres'},{username,<<"postgres">>},{password,<<"postgres">>},{database,<<"consumer_dev">>},{hostname,<<"localhost">>},{pool_size,10},{pool,'Elixir.DBConnection.Poolboy'}]}},...]}}}},...} in application_master:init/4 line 134
2018-04-09 16:06:59.832 [error] <0.191.0> Supervisor 'Elixir.Logger.Supervisor' had child 'Elixir.Logger.ErrorHandler' started with 'Elixir.Logger.Watcher':start_link({error_logger,'Elixir.Logger.ErrorHandler',{true,false,500}}) at <0.196.0> exit with reason normal in context child_terminated
2018-04-09 16:06:59.929 [error] <0.252.0>@Elixir.GenServer:call CRASH REPORT Process <0.252.0> with 0 neighbours exited with reason: no such process or port in call to 'Elixir.GenServer':call('Elixir.Ecto.Registry', {associate,<0.252.0>,{'Elixir.Consumer.Repo','Elixir.Consumer.Repo.Pool',[{name,'Elixir.Consumer.Repo.Pool'},...]}}, 5000) in 'Elixir.GenServer':call/3 line 824
2018-04-09 16:06:59.929 [error] <0.251.0>@Elixir.GenServer:call Supervisor 'Elixir.Consumer.Supervisor' had child 'Elixir.Consumer.Repo' started with 'Elixir.Consumer.Repo':start_link() at undefined exit with reason no such process or port in call to 'Elixir.GenServer':call('Elixir.Ecto.Registry', {associate,<0.252.0>,{'Elixir.Consumer.Repo','Elixir.Consumer.Repo.Pool',[{name,'Elixir.Consumer.Repo.Pool'},...]}}, 5000) in context start_error
2018-04-09 16:06:59.929 [error] <0.249.0> CRASH REPORT Process <0.249.0> with 0 neighbours exited with reason: {{shutdown,{failed_to_start_child,'Elixir.Consumer.Repo',{noproc,{'Elixir.GenServer',call,['Elixir.Ecto.Registry',{associate,<0.252.0>,{'Elixir.Consumer.Repo','Elixir.Consumer.Repo.Pool',[{name,'Elixir.Consumer.Repo.Pool'},{otp_app,consumer},{repo,'Elixir.Consumer.Repo'},{timeout,15000},{pool_timeout,5000},{adapter,'Elixir.Ecto.Adapters.Postgres'},{username,<<"postgres">>},{password,<<"postgres">>},{database,<<"consumer_dev">>},{hostname,<<"localhost">>},{pool_size,10},{pool,'Elixir.DBConnection.Poolboy'}]}},...]}}}},...} in application_master:init/4 line 134
2018-04-09 16:12:05.802 [error] <0.594.0> Supervisor 'Elixir.Logger.Supervisor' had child 'Elixir.Logger.ErrorHandler' started with 'Elixir.Logger.Watcher':start_link({error_logger,'Elixir.Logger.ErrorHandler',{true,false,500}}) at <0.599.0> exit with reason normal in context child_terminated
2018-04-09 16:12:05.882 [error] <0.655.0>@Elixir.GenServer:call CRASH REPORT Process <0.655.0> with 0 neighbours exited with reason: no such process or port in call to 'Elixir.GenServer':call('Elixir.Ecto.Registry', {associate,<0.655.0>,{'Elixir.Consumer.Repo','Elixir.Consumer.Repo.Pool',[{name,'Elixir.Consumer.Repo.Pool'},...]}}, 5000) in 'Elixir.GenServer':call/3 line 824
2018-04-09 16:12:05.882 [error] <0.654.0>@Elixir.GenServer:call Supervisor 'Elixir.Consumer.Supervisor' had child 'Elixir.Consumer.Repo' started with 'Elixir.Consumer.Repo':start_link() at undefined exit with reason no such process or port in call to 'Elixir.GenServer':call('Elixir.Ecto.Registry', {associate,<0.655.0>,{'Elixir.Consumer.Repo','Elixir.Consumer.Repo.Pool',[{name,'Elixir.Consumer.Repo.Pool'},...]}}, 5000) in context start_error
2018-04-09 16:12:33.275 [error] <0.313.0> Supervisor 'Elixir.Logger.Supervisor' had child 'Elixir.Logger.ErrorHandler' started with 'Elixir.Logger.Watcher':start_link({error_logger,'Elixir.Logger.ErrorHandler',{true,false,500}}) at <0.318.0> exit with reason normal in context child_terminated
2018-04-09 16:17:20.645 [error] <0.313.0> Supervisor 'Elixir.Logger.Supervisor' had child 'Elixir.Logger.ErrorHandler' started with 'Elixir.Logger.Watcher':start_link({error_logger,'Elixir.Logger.ErrorHandler',{true,false,500}}) at <0.318.0> exit with reason normal in context child_terminated
2018-04-09 16:17:44.852 [error] <0.449.0> Supervisor 'Elixir.Logger.Supervisor' had child 'Elixir.Logger.ErrorHandler' started with 'Elixir.Logger.Watcher':start_link({error_logger,'Elixir.Logger.ErrorHandler',{true,false,500}}) at <0.454.0> exit with reason normal in context child_terminated
2018-04-09 16:26:08.694 [error] <0.732.0> Ranch listener 'Elixir.ConsumerWeb.Endpoint.HTTP' terminated with reason: {{undef,[{'Elixir.ConsumerWeb.RoomChannel','__socket__',[private],[]},{'Elixir.Phoenix.Socket.Transport',build_channel_socket,5,[{file,"lib/phoenix/socket/transport.ex"},{line,261}]},{'Elixir.Phoenix.Socket.Transport',do_dispatch,3,[{file,"lib/phoenix/socket/transport.ex"},{line,267}]},{'Elixir.Phoenix.Transports.WebSocket',ws_handle,3,[{file,"lib/phoenix/transports/websocket.ex"},{line,123}]},{'Elixir.Phoenix.Endpoint.CowboyWebSocket',websocket_handle,3,[{file,"lib/phoenix/endpoint/cowboy..."},...]},...]},...}
2018-04-09 16:26:12.221 [error] <0.740.0> Ranch listener 'Elixir.ConsumerWeb.Endpoint.HTTP' terminated with reason: {{undef,[{'Elixir.ConsumerWeb.RoomChannel','__socket__',[private],[]},{'Elixir.Phoenix.Socket.Transport',build_channel_socket,5,[{file,"lib/phoenix/socket/transport.ex"},{line,261}]},{'Elixir.Phoenix.Socket.Transport',do_dispatch,3,[{file,"lib/phoenix/socket/transport.ex"},{line,267}]},{'Elixir.Phoenix.Transports.WebSocket',ws_handle,3,[{file,"lib/phoenix/transports/websocket.ex"},{line,123}]},{'Elixir.Phoenix.Endpoint.CowboyWebSocket',websocket_handle,3,[{file,"lib/phoenix/endpoint/cowboy..."},...]},...]},...}
2018-04-09 16:26:16.327 [error] <0.745.0> Ranch listener 'Elixir.ConsumerWeb.Endpoint.HTTP' terminated with reason: {{undef,[{'Elixir.ConsumerWeb.RoomChannel','__socket__',[private],[]},{'Elixir.Phoenix.Socket.Transport',build_channel_socket,5,[{file,"lib/phoenix/socket/transport.ex"},{line,261}]},{'Elixir.Phoenix.Socket.Transport',do_dispatch,3,[{file,"lib/phoenix/socket/transport.ex"},{line,267}]},{'Elixir.Phoenix.Transports.WebSocket',ws_handle,3,[{file,"lib/phoenix/transports/websocket.ex"},{line,123}]},{'Elixir.Phoenix.Endpoint.CowboyWebSocket',websocket_handle,3,[{file,"lib/phoenix/endpoint/cowboy..."},...]},...]},...}
2018-04-09 16:26:22.570 [error] <0.747.0> Ranch listener 'Elixir.ConsumerWeb.Endpoint.HTTP' terminated with reason: {{undef,[{'Elixir.ConsumerWeb.RoomChannel','__socket__',[private],[]},{'Elixir.Phoenix.Socket.Transport',build_channel_socket,5,[{file,"lib/phoenix/socket/transport.ex"},{line,261}]},{'Elixir.Phoenix.Socket.Transport',do_dispatch,3,[{file,"lib/phoenix/socket/transport.ex"},{line,267}]},{'Elixir.Phoenix.Transports.WebSocket',ws_handle,3,[{file,"lib/phoenix/transports/websocket.ex"},{line,123}]},{'Elixir.Phoenix.Endpoint.CowboyWebSocket',websocket_handle,3,[{file,"lib/phoenix/endpoint/cowboy..."},...]},...]},...}
2018-04-09 16:26:33.196 [error] <0.749.0> Ranch listener 'Elixir.ConsumerWeb.Endpoint.HTTP' terminated with reason: {{undef,[{'Elixir.ConsumerWeb.RoomChannel','__socket__',[private],[]},{'Elixir.Phoenix.Socket.Transport',build_channel_socket,5,[{file,"lib/phoenix/socket/transport.ex"},{line,261}]},{'Elixir.Phoenix.Socket.Transport',do_dispatch,3,[{file,"lib/phoenix/socket/transport.ex"},{line,267}]},{'Elixir.Phoenix.Transports.WebSocket',ws_handle,3,[{file,"lib/phoenix/transports/websocket.ex"},{line,123}]},{'Elixir.Phoenix.Endpoint.CowboyWebSocket',websocket_handle,3,[{file,"lib/phoenix/endpoint/cowboy..."},...]},...]},...}
2018-04-09 16:26:44.512 [error] <0.751.0> Ranch listener 'Elixir.ConsumerWeb.Endpoint.HTTP' terminated with reason: {{undef,[{'Elixir.ConsumerWeb.RoomChannel','__socket__',[private],[]},{'Elixir.Phoenix.Socket.Transport',build_channel_socket,5,[{file,"lib/phoenix/socket/transport.ex"},{line,261}]},{'Elixir.Phoenix.Socket.Transport',do_dispatch,3,[{file,"lib/phoenix/socket/transport.ex"},{line,267}]},{'Elixir.Phoenix.Transports.WebSocket',ws_handle,3,[{file,"lib/phoenix/transports/websocket.ex"},{line,123}]},{'Elixir.Phoenix.Endpoint.CowboyWebSocket',websocket_handle,3,[{file,"lib/phoenix/endpoint/cowboy..."},...]},...]},...}
2018-04-09 16:26:55.260 [error] <0.753.0> Ranch listener 'Elixir.ConsumerWeb.Endpoint.HTTP' terminated with reason: {{undef,[{'Elixir.ConsumerWeb.RoomChannel','__socket__',[private],[]},{'Elixir.Phoenix.Socket.Transport',build_channel_socket,5,[{file,"lib/phoenix/socket/transport.ex"},{line,261}]},{'Elixir.Phoenix.Socket.Transport',do_dispatch,3,[{file,"lib/phoenix/socket/transport.ex"},{line,267}]},{'Elixir.Phoenix.Transports.WebSocket',ws_handle,3,[{file,"lib/phoenix/transports/websocket.ex"},{line,123}]},{'Elixir.Phoenix.Endpoint.CowboyWebSocket',websocket_handle,3,[{file,"lib/phoenix/endpoint/cowboy..."},...]},...]},...}
2018-04-09 16:27:06.561 [error] <0.755.0> Ranch listener 'Elixir.ConsumerWeb.Endpoint.HTTP' terminated with reason: {{undef,[{'Elixir.ConsumerWeb.RoomChannel','__socket__',[private],[]},{'Elixir.Phoenix.Socket.Transport',build_channel_socket,5,[{file,"lib/phoenix/socket/transport.ex"},{line,261}]},{'Elixir.Phoenix.Socket.Transport',do_dispatch,3,[{file,"lib/phoenix/socket/transport.ex"},{line,267}]},{'Elixir.Phoenix.Transports.WebSocket',ws_handle,3,[{file,"lib/phoenix/transports/websocket.ex"},{line,123}]},{'Elixir.Phoenix.Endpoint.CowboyWebSocket',websocket_handle,3,[{file,"lib/phoenix/endpoint/cowboy..."},...]},...]},...}
2018-04-09 16:27:17.134 [error] <0.757.0> Ranch listener 'Elixir.ConsumerWeb.Endpoint.HTTP' terminated with reason: {{undef,[{'Elixir.ConsumerWeb.RoomChannel','__socket__',[private],[]},{'Elixir.Phoenix.Socket.Transport',build_channel_socket,5,[{file,"lib/phoenix/socket/transport.ex"},{line,261}]},{'Elixir.Phoenix.Socket.Transport',do_dispatch,3,[{file,"lib/phoenix/socket/transport.ex"},{line,267}]},{'Elixir.Phoenix.Transports.WebSocket',ws_handle,3,[{file,"lib/phoenix/transports/websocket.ex"},{line,123}]},{'Elixir.Phoenix.Endpoint.CowboyWebSocket',websocket_handle,3,[{file,"lib/phoenix/endpoint/cowboy..."},...]},...]},...}
2018-04-09 16:46:12.714 [error] <0.201.0> Supervisor 'Elixir.Logger.Supervisor' had child 'Elixir.Logger.ErrorHandler' started with 'Elixir.Logger.Watcher':start_link({error_logger,'Elixir.Logger.ErrorHandler',{true,false,500}}) at <0.206.0> exit with reason normal in context child_terminated
2018-04-09 16:47:11.481 [error] <0.200.0> Supervisor 'Elixir.Logger.Supervisor' had child 'Elixir.Logger.ErrorHandler' started with 'Elixir.Logger.Watcher':start_link({error_logger,'Elixir.Logger.ErrorHandler',{true,false,500}}) at <0.205.0> exit with reason normal in context child_terminated
2018-04-09 16:49:25.605 [error] <0.192.0> Supervisor 'Elixir.Logger.Supervisor' had child 'Elixir.Logger.ErrorHandler' started with 'Elixir.Logger.Watcher':start_link({error_logger,'Elixir.Logger.ErrorHandler',{true,false,500}}) at <0.197.0> exit with reason normal in context child_terminated
2018-04-09 16:51:38.916 [error] <0.192.0> Supervisor 'Elixir.Logger.Supervisor' had child 'Elixir.Logger.ErrorHandler' started with 'Elixir.Logger.Watcher':start_link({error_logger,'Elixir.Logger.ErrorHandler',{true,false,500}}) at <0.197.0> exit with reason normal in context child_terminated
2018-04-09 16:53:26.351 [error] <0.200.0> Supervisor 'Elixir.Logger.Supervisor' had child 'Elixir.Logger.ErrorHandler' started with 'Elixir.Logger.Watcher':start_link({error_logger,'Elixir.Logger.ErrorHandler',{true,false,500}}) at <0.205.0> exit with reason normal in context child_terminated
